<robot xmlns:xacro="http://www.ros.org/wiki/xacro" name="leg_wheel">

  <xacro:macro name="leg" params="prefix *origin">
     <link name="${prefix}_leg">
       <inertial>
          <origin xyz="0 0 0" rpy="0 0 0"/>
          <mass value="0.130"/>
          <inertia ixx="1.75e-5" ixy="0" ixz="0" iyy="1.75e-5" iyz="0" izz="1.75e-5"/>
       </inertial>
       <visual>
	<origin xyz="0 0 0" rpy="${3.1415/2} 0 0"/>
	<geometry>
	  <box size="0.2 0.2 0.6"/>
	</geometry>
	<material name="Leg_Blue">
	  <color rgba="${30/255} ${144/255} ${255/255}  0.8"/>
	</material>
      </visual>
      <collision>
	<origin xyz="0 0 0" rpy="${3.1415/2} 0 0"/>
	<geometry>
	  <box size="0.2 0.2 0.6"/>
	</geometry>
	<material name="blue">
	  <color rgba="0.0 1.0 0.0 0.5"/>
	</material>
      </collision>
     </link> 
     
     
     <xacro:wheel prefix="${prefix}"/>
     
     <joint name="${prefix}_leg_joint" type="fixed">
      <parent link="base_link"/>
      <child  link="${prefix}_leg"/>
      <xacro:insert_block name="origin" />
      <axis xyz="0 1 0"/>
    </joint>
     
     <joint name="${prefix}_Wheel" type="continuous">
      <parent link="${prefix}_leg"/>
      <child  link="${prefix}_wheel"/>
      <origin xyz="0.0 0.2 0" rpy="${-3.1415/2} 0 ${-3.1415/2}"/>
      <axis xyz="0 1 0"/>
    </joint>
  </xacro:macro>
  
  <xacro:macro name="wheel" params="prefix">
       <link name="${prefix}_wheel">
       <inertial>
          <origin xyz="0 0 0" rpy="0 0 0"/>
          <mass value="0.030"/>
          <inertia ixx="1.75e-5" ixy="0" ixz="0" iyy="1.75e-5" iyz="0" izz="1.75e-5"/>
       </inertial>
       <visual>
	<origin xyz="0 0 0" rpy="${3.1415/2} 0 0"/>
	<geometry>
	  <cylinder length="0.05" radius="0.2"/>
	</geometry>
	<material name="blue">
	  <color rgba="${255/255} ${0/255} ${0/255}  0.8"/>
	</material>
      </visual>
      <collision>
	<origin xyz="0 0 0" rpy="${3.1415/2} 0 0"/>
	<geometry>
	  <cylinder length="0.05" radius="0.2"/>
	</geometry>
	<material name="blue">
	  <color rgba="0.0 1.0 0.0 0.5"/>
	</material>
      </collision>
     
     </link>  
  </xacro:macro>
  
</robot>
